Traceback (most recent call last):
  File "/Users/eduardoperezbrito/omega-vx/.venv/lib/python3.9/site-packages/urllib3/connection.py", line 174, in _new_conn
    conn = connection.create_connection(
  File "/Users/eduardoperezbrito/omega-vx/.venv/lib/python3.9/site-packages/urllib3/util/connection.py", line 72, in create_connection
    for res in socket.getaddrinfo(host, port, family, socket.SOCK_STREAM):
  File "/Library/Developer/CommandLineTools/Library/Frameworks/Python3.framework/Versions/3.9/lib/python3.9/socket.py", line 953, in getaddrinfo
    for res in _socket.getaddrinfo(host, port, family, type, proto, flags):
socket.gaierror: [Errno 8] nodename nor servname provided, or not known

During handling of the above exception, another exception occurred:

Traceback (most recent call last):
  File "/Users/eduardoperezbrito/omega-vx/.venv/lib/python3.9/site-packages/urllib3/connectionpool.py", line 716, in urlopen
    httplib_response = self._make_request(
  File "/Users/eduardoperezbrito/omega-vx/.venv/lib/python3.9/site-packages/urllib3/connectionpool.py", line 404, in _make_request
    self._validate_conn(conn)
  File "/Users/eduardoperezbrito/omega-vx/.venv/lib/python3.9/site-packages/urllib3/connectionpool.py", line 1061, in _validate_conn
    conn.connect()
  File "/Users/eduardoperezbrito/omega-vx/.venv/lib/python3.9/site-packages/urllib3/connection.py", line 363, in connect
    self.sock = conn = self._new_conn()
  File "/Users/eduardoperezbrito/omega-vx/.venv/lib/python3.9/site-packages/urllib3/connection.py", line 186, in _new_conn
    raise NewConnectionError(
urllib3.exceptions.NewConnectionError: <urllib3.connection.HTTPSConnection object at 0x104a08310>: Failed to establish a new connection: [Errno 8] nodename nor servname provided, or not known

During handling of the above exception, another exception occurred:

Traceback (most recent call last):
  File "/Users/eduardoperezbrito/omega-vx/.venv/lib/python3.9/site-packages/requests/adapters.py", line 667, in send
    resp = conn.urlopen(
  File "/Users/eduardoperezbrito/omega-vx/.venv/lib/python3.9/site-packages/urllib3/connectionpool.py", line 802, in urlopen
    retries = retries.increment(
  File "/Users/eduardoperezbrito/omega-vx/.venv/lib/python3.9/site-packages/urllib3/util/retry.py", line 594, in increment
    raise MaxRetryError(_pool, url, error or ResponseError(cause))
urllib3.exceptions.MaxRetryError: HTTPSConnectionPool(host='paper-api.alpaca.markets', port=443): Max retries exceeded with url: /v2/account (Caused by NewConnectionError('<urllib3.connection.HTTPSConnection object at 0x104a08310>: Failed to establish a new connection: [Errno 8] nodename nor servname provided, or not known'))

During handling of the above exception, another exception occurred:

Traceback (most recent call last):
  File "/Users/eduardoperezbrito/omega-vx/portfolio_snapshot.py", line 17, in <module>
    account = api.get_account()
  File "/Users/eduardoperezbrito/omega-vx/.venv/lib/python3.9/site-packages/alpaca_trade_api/rest.py", line 280, in get_account
    resp = self.get('/account')
  File "/Users/eduardoperezbrito/omega-vx/.venv/lib/python3.9/site-packages/alpaca_trade_api/rest.py", line 254, in get
    return self._request('GET', path, data)
  File "/Users/eduardoperezbrito/omega-vx/.venv/lib/python3.9/site-packages/alpaca_trade_api/rest.py", line 222, in _request
    return self._one_request(method, url, opts, retry)
  File "/Users/eduardoperezbrito/omega-vx/.venv/lib/python3.9/site-packages/alpaca_trade_api/rest.py", line 241, in _one_request
    resp = self._session.request(method, url, **opts)
  File "/Users/eduardoperezbrito/omega-vx/.venv/lib/python3.9/site-packages/requests/sessions.py", line 589, in request
    resp = self.send(prep, **send_kwargs)
  File "/Users/eduardoperezbrito/omega-vx/.venv/lib/python3.9/site-packages/requests/sessions.py", line 703, in send
    r = adapter.send(request, **kwargs)
  File "/Users/eduardoperezbrito/omega-vx/.venv/lib/python3.9/site-packages/requests/adapters.py", line 700, in send
    raise ConnectionError(e, request=request)
requests.exceptions.ConnectionError: HTTPSConnectionPool(host='paper-api.alpaca.markets', port=443): Max retries exceeded with url: /v2/account (Caused by NewConnectionError('<urllib3.connection.HTTPSConnection object at 0x104a08310>: Failed to establish a new connection: [Errno 8] nodename nor servname provided, or not known'))
âœ… Portfolio snapshot logged:
ðŸ•’ Time: 2025-08-05 16:08:58
ðŸ’¼ Equity: $99995.85
ðŸ’µ Cash: $99995.85
ðŸ“ˆ Portfolio Value: $99995.85
/Users/eduardoperezbrito/omega-vx/.venv/lib/python3.9/site-packages/urllib3/__init__.py:35: NotOpenSSLWarning: urllib3 v2 only supports OpenSSL 1.1.1+, currently the 'ssl' module is compiled with 'LibreSSL 2.8.3'. See: https://github.com/urllib3/urllib3/issues/3020
  warnings.warn(
Traceback (most recent call last):
  File "/Users/eduardoperezbrito/omega-vx/.venv/lib/python3.9/site-packages/urllib3/connection.py", line 198, in _new_conn
    sock = connection.create_connection(
  File "/Users/eduardoperezbrito/omega-vx/.venv/lib/python3.9/site-packages/urllib3/util/connection.py", line 60, in create_connection
    for res in socket.getaddrinfo(host, port, family, socket.SOCK_STREAM):
  File "/Library/Developer/CommandLineTools/Library/Frameworks/Python3.framework/Versions/3.9/lib/python3.9/socket.py", line 953, in getaddrinfo
    for res in _socket.getaddrinfo(host, port, family, type, proto, flags):
socket.gaierror: [Errno 8] nodename nor servname provided, or not known

The above exception was the direct cause of the following exception:

Traceback (most recent call last):
  File "/Users/eduardoperezbrito/omega-vx/.venv/lib/python3.9/site-packages/urllib3/connectionpool.py", line 787, in urlopen
    response = self._make_request(
  File "/Users/eduardoperezbrito/omega-vx/.venv/lib/python3.9/site-packages/urllib3/connectionpool.py", line 488, in _make_request
    raise new_e
  File "/Users/eduardoperezbrito/omega-vx/.venv/lib/python3.9/site-packages/urllib3/connectionpool.py", line 464, in _make_request
    self._validate_conn(conn)
  File "/Users/eduardoperezbrito/omega-vx/.venv/lib/python3.9/site-packages/urllib3/connectionpool.py", line 1093, in _validate_conn
    conn.connect()
  File "/Users/eduardoperezbrito/omega-vx/.venv/lib/python3.9/site-packages/urllib3/connection.py", line 753, in connect
    self.sock = sock = self._new_conn()
  File "/Users/eduardoperezbrito/omega-vx/.venv/lib/python3.9/site-packages/urllib3/connection.py", line 205, in _new_conn
    raise NameResolutionError(self.host, self, e) from e
urllib3.exceptions.NameResolutionError: <urllib3.connection.HTTPSConnection object at 0x107046730>: Failed to resolve 'paper-api.alpaca.markets' ([Errno 8] nodename nor servname provided, or not known)

The above exception was the direct cause of the following exception:

Traceback (most recent call last):
  File "/Users/eduardoperezbrito/omega-vx/.venv/lib/python3.9/site-packages/requests/adapters.py", line 667, in send
    resp = conn.urlopen(
  File "/Users/eduardoperezbrito/omega-vx/.venv/lib/python3.9/site-packages/urllib3/connectionpool.py", line 841, in urlopen
    retries = retries.increment(
  File "/Users/eduardoperezbrito/omega-vx/.venv/lib/python3.9/site-packages/urllib3/util/retry.py", line 519, in increment
    raise MaxRetryError(_pool, url, reason) from reason  # type: ignore[arg-type]
urllib3.exceptions.MaxRetryError: HTTPSConnectionPool(host='paper-api.alpaca.markets', port=443): Max retries exceeded with url: /v2/account (Caused by NameResolutionError("<urllib3.connection.HTTPSConnection object at 0x107046730>: Failed to resolve 'paper-api.alpaca.markets' ([Errno 8] nodename nor servname provided, or not known)"))

During handling of the above exception, another exception occurred:

Traceback (most recent call last):
  File "/Users/eduardoperezbrito/omega-vx/portfolio_snapshot.py", line 17, in <module>
    account = api.get_account()
  File "/Users/eduardoperezbrito/omega-vx/.venv/lib/python3.9/site-packages/alpaca_trade_api/rest.py", line 280, in get_account
    resp = self.get('/account')
  File "/Users/eduardoperezbrito/omega-vx/.venv/lib/python3.9/site-packages/alpaca_trade_api/rest.py", line 254, in get
    return self._request('GET', path, data)
  File "/Users/eduardoperezbrito/omega-vx/.venv/lib/python3.9/site-packages/alpaca_trade_api/rest.py", line 222, in _request
    return self._one_request(method, url, opts, retry)
  File "/Users/eduardoperezbrito/omega-vx/.venv/lib/python3.9/site-packages/alpaca_trade_api/rest.py", line 241, in _one_request
    resp = self._session.request(method, url, **opts)
  File "/Users/eduardoperezbrito/omega-vx/.venv/lib/python3.9/site-packages/requests/sessions.py", line 589, in request
    resp = self.send(prep, **send_kwargs)
  File "/Users/eduardoperezbrito/omega-vx/.venv/lib/python3.9/site-packages/requests/sessions.py", line 703, in send
    r = adapter.send(request, **kwargs)
  File "/Users/eduardoperezbrito/omega-vx/.venv/lib/python3.9/site-packages/requests/adapters.py", line 700, in send
    raise ConnectionError(e, request=request)
requests.exceptions.ConnectionError: HTTPSConnectionPool(host='paper-api.alpaca.markets', port=443): Max retries exceeded with url: /v2/account (Caused by NameResolutionError("<urllib3.connection.HTTPSConnection object at 0x107046730>: Failed to resolve 'paper-api.alpaca.markets' ([Errno 8] nodename nor servname provided, or not known)"))
/Users/eduardoperezbrito/omega-vx/.venv/lib/python3.9/site-packages/urllib3/__init__.py:35: NotOpenSSLWarning: urllib3 v2 only supports OpenSSL 1.1.1+, currently the 'ssl' module is compiled with 'LibreSSL 2.8.3'. See: https://github.com/urllib3/urllib3/issues/3020
  warnings.warn(
âœ… Portfolio snapshot logged:
ðŸ•’ Time: 2025-08-07 15:59:01
ðŸ’¼ Equity: $100278.09
ðŸ’µ Cash: $88212.53
ðŸ“ˆ Portfolio Value: $100278.09
/Users/eduardoperezbrito/omega-vx/.venv/lib/python3.9/site-packages/urllib3/__init__.py:35: NotOpenSSLWarning: urllib3 v2 only supports OpenSSL 1.1.1+, currently the 'ssl' module is compiled with 'LibreSSL 2.8.3'. See: https://github.com/urllib3/urllib3/issues/3020
  warnings.warn(
âœ… Portfolio snapshot logged:
ðŸ•’ Time: 2025-08-11 15:59:01
ðŸ’¼ Equity: $100319.13
ðŸ’µ Cash: $100137.20
ðŸ“ˆ Portfolio Value: $100319.13
/Users/eduardoperezbrito/omega-vx/.venv/lib/python3.9/site-packages/urllib3/__init__.py:35: NotOpenSSLWarning: urllib3 v2 only supports OpenSSL 1.1.1+, currently the 'ssl' module is compiled with 'LibreSSL 2.8.3'. See: https://github.com/urllib3/urllib3/issues/3020
  warnings.warn(
âœ… Portfolio snapshot logged:
ðŸ•’ Time: 2025-08-15 15:59:02
ðŸ’¼ Equity: $96711.91
ðŸ’µ Cash: $19155.47
ðŸ“ˆ Portfolio Value: $96711.91
/Users/eduardoperezbrito/omega-vx/.venv/lib/python3.9/site-packages/urllib3/__init__.py:35: NotOpenSSLWarning: urllib3 v2 only supports OpenSSL 1.1.1+, currently the 'ssl' module is compiled with 'LibreSSL 2.8.3'. See: https://github.com/urllib3/urllib3/issues/3020
  warnings.warn(
Traceback (most recent call last):
  File "/Users/eduardoperezbrito/omega-vx/.venv/lib/python3.9/site-packages/urllib3/connection.py", line 198, in _new_conn
    sock = connection.create_connection(
  File "/Users/eduardoperezbrito/omega-vx/.venv/lib/python3.9/site-packages/urllib3/util/connection.py", line 60, in create_connection
    for res in socket.getaddrinfo(host, port, family, socket.SOCK_STREAM):
  File "/Library/Developer/CommandLineTools/Library/Frameworks/Python3.framework/Versions/3.9/lib/python3.9/socket.py", line 953, in getaddrinfo
    for res in _socket.getaddrinfo(host, port, family, type, proto, flags):
socket.gaierror: [Errno 8] nodename nor servname provided, or not known

The above exception was the direct cause of the following exception:

Traceback (most recent call last):
  File "/Users/eduardoperezbrito/omega-vx/.venv/lib/python3.9/site-packages/urllib3/connectionpool.py", line 787, in urlopen
    response = self._make_request(
  File "/Users/eduardoperezbrito/omega-vx/.venv/lib/python3.9/site-packages/urllib3/connectionpool.py", line 488, in _make_request
    raise new_e
  File "/Users/eduardoperezbrito/omega-vx/.venv/lib/python3.9/site-packages/urllib3/connectionpool.py", line 464, in _make_request
    self._validate_conn(conn)
  File "/Users/eduardoperezbrito/omega-vx/.venv/lib/python3.9/site-packages/urllib3/connectionpool.py", line 1093, in _validate_conn
    conn.connect()
  File "/Users/eduardoperezbrito/omega-vx/.venv/lib/python3.9/site-packages/urllib3/connection.py", line 753, in connect
    self.sock = sock = self._new_conn()
  File "/Users/eduardoperezbrito/omega-vx/.venv/lib/python3.9/site-packages/urllib3/connection.py", line 205, in _new_conn
    raise NameResolutionError(self.host, self, e) from e
urllib3.exceptions.NameResolutionError: <urllib3.connection.HTTPSConnection object at 0x106764340>: Failed to resolve 'api.alpaca.markets' ([Errno 8] nodename nor servname provided, or not known)

The above exception was the direct cause of the following exception:

Traceback (most recent call last):
  File "/Users/eduardoperezbrito/omega-vx/.venv/lib/python3.9/site-packages/requests/adapters.py", line 667, in send
    resp = conn.urlopen(
  File "/Users/eduardoperezbrito/omega-vx/.venv/lib/python3.9/site-packages/urllib3/connectionpool.py", line 841, in urlopen
    retries = retries.increment(
  File "/Users/eduardoperezbrito/omega-vx/.venv/lib/python3.9/site-packages/urllib3/util/retry.py", line 519, in increment
    raise MaxRetryError(_pool, url, reason) from reason  # type: ignore[arg-type]
urllib3.exceptions.MaxRetryError: HTTPSConnectionPool(host='api.alpaca.markets', port=443): Max retries exceeded with url: /v2/account (Caused by NameResolutionError("<urllib3.connection.HTTPSConnection object at 0x106764340>: Failed to resolve 'api.alpaca.markets' ([Errno 8] nodename nor servname provided, or not known)"))

During handling of the above exception, another exception occurred:

Traceback (most recent call last):
  File "/Users/eduardoperezbrito/omega-vx/portfolio_snapshot.py", line 17, in <module>
    account = api.get_account()
  File "/Users/eduardoperezbrito/omega-vx/.venv/lib/python3.9/site-packages/alpaca_trade_api/rest.py", line 280, in get_account
    resp = self.get('/account')
  File "/Users/eduardoperezbrito/omega-vx/.venv/lib/python3.9/site-packages/alpaca_trade_api/rest.py", line 254, in get
    return self._request('GET', path, data)
  File "/Users/eduardoperezbrito/omega-vx/.venv/lib/python3.9/site-packages/alpaca_trade_api/rest.py", line 222, in _request
    return self._one_request(method, url, opts, retry)
  File "/Users/eduardoperezbrito/omega-vx/.venv/lib/python3.9/site-packages/alpaca_trade_api/rest.py", line 241, in _one_request
    resp = self._session.request(method, url, **opts)
  File "/Users/eduardoperezbrito/omega-vx/.venv/lib/python3.9/site-packages/requests/sessions.py", line 589, in request
    resp = self.send(prep, **send_kwargs)
  File "/Users/eduardoperezbrito/omega-vx/.venv/lib/python3.9/site-packages/requests/sessions.py", line 703, in send
    r = adapter.send(request, **kwargs)
  File "/Users/eduardoperezbrito/omega-vx/.venv/lib/python3.9/site-packages/requests/adapters.py", line 700, in send
    raise ConnectionError(e, request=request)
requests.exceptions.ConnectionError: HTTPSConnectionPool(host='api.alpaca.markets', port=443): Max retries exceeded with url: /v2/account (Caused by NameResolutionError("<urllib3.connection.HTTPSConnection object at 0x106764340>: Failed to resolve 'api.alpaca.markets' ([Errno 8] nodename nor servname provided, or not known)"))
/Users/eduardoperezbrito/omega-vx/.venv/lib/python3.9/site-packages/urllib3/__init__.py:35: NotOpenSSLWarning: urllib3 v2 only supports OpenSSL 1.1.1+, currently the 'ssl' module is compiled with 'LibreSSL 2.8.3'. See: https://github.com/urllib3/urllib3/issues/3020
  warnings.warn(
Traceback (most recent call last):
  File "/Users/eduardoperezbrito/omega-vx/portfolio_snapshot.py", line 17, in <module>
    account = api.get_account()
  File "/Users/eduardoperezbrito/omega-vx/.venv/lib/python3.9/site-packages/alpaca_trade_api/rest.py", line 280, in get_account
    resp = self.get('/account')
  File "/Users/eduardoperezbrito/omega-vx/.venv/lib/python3.9/site-packages/alpaca_trade_api/rest.py", line 254, in get
    return self._request('GET', path, data)
  File "/Users/eduardoperezbrito/omega-vx/.venv/lib/python3.9/site-packages/alpaca_trade_api/rest.py", line 222, in _request
    return self._one_request(method, url, opts, retry)
  File "/Users/eduardoperezbrito/omega-vx/.venv/lib/python3.9/site-packages/alpaca_trade_api/rest.py", line 248, in _one_request
    raise_api_error(resp, http_error)
  File "/Users/eduardoperezbrito/omega-vx/.venv/lib/python3.9/site-packages/alpaca_trade_api/rest.py", line 83, in raise_api_error
    raise APIError(error, http_error) from None
alpaca_trade_api.rest.APIError: request is not authorized
/Users/eduardoperezbrito/omega-vx/.venv/lib/python3.9/site-packages/urllib3/__init__.py:35: NotOpenSSLWarning: urllib3 v2 only supports OpenSSL 1.1.1+, currently the 'ssl' module is compiled with 'LibreSSL 2.8.3'. See: https://github.com/urllib3/urllib3/issues/3020
  warnings.warn(
Traceback (most recent call last):
  File "/Users/eduardoperezbrito/omega-vx/.venv/lib/python3.9/site-packages/urllib3/connection.py", line 198, in _new_conn
    sock = connection.create_connection(
  File "/Users/eduardoperezbrito/omega-vx/.venv/lib/python3.9/site-packages/urllib3/util/connection.py", line 60, in create_connection
    for res in socket.getaddrinfo(host, port, family, socket.SOCK_STREAM):
  File "/Library/Developer/CommandLineTools/Library/Frameworks/Python3.framework/Versions/3.9/lib/python3.9/socket.py", line 953, in getaddrinfo
    for res in _socket.getaddrinfo(host, port, family, type, proto, flags):
socket.gaierror: [Errno 8] nodename nor servname provided, or not known

The above exception was the direct cause of the following exception:

Traceback (most recent call last):
  File "/Users/eduardoperezbrito/omega-vx/.venv/lib/python3.9/site-packages/urllib3/connectionpool.py", line 787, in urlopen
    response = self._make_request(
  File "/Users/eduardoperezbrito/omega-vx/.venv/lib/python3.9/site-packages/urllib3/connectionpool.py", line 488, in _make_request
    raise new_e
  File "/Users/eduardoperezbrito/omega-vx/.venv/lib/python3.9/site-packages/urllib3/connectionpool.py", line 464, in _make_request
    self._validate_conn(conn)
  File "/Users/eduardoperezbrito/omega-vx/.venv/lib/python3.9/site-packages/urllib3/connectionpool.py", line 1093, in _validate_conn
    conn.connect()
  File "/Users/eduardoperezbrito/omega-vx/.venv/lib/python3.9/site-packages/urllib3/connection.py", line 753, in connect
    self.sock = sock = self._new_conn()
  File "/Users/eduardoperezbrito/omega-vx/.venv/lib/python3.9/site-packages/urllib3/connection.py", line 205, in _new_conn
    raise NameResolutionError(self.host, self, e) from e
urllib3.exceptions.NameResolutionError: <urllib3.connection.HTTPSConnection object at 0x110bcd280>: Failed to resolve 'api.alpaca.markets' ([Errno 8] nodename nor servname provided, or not known)

The above exception was the direct cause of the following exception:

Traceback (most recent call last):
  File "/Users/eduardoperezbrito/omega-vx/.venv/lib/python3.9/site-packages/requests/adapters.py", line 667, in send
    resp = conn.urlopen(
  File "/Users/eduardoperezbrito/omega-vx/.venv/lib/python3.9/site-packages/urllib3/connectionpool.py", line 841, in urlopen
    retries = retries.increment(
  File "/Users/eduardoperezbrito/omega-vx/.venv/lib/python3.9/site-packages/urllib3/util/retry.py", line 519, in increment
    raise MaxRetryError(_pool, url, reason) from reason  # type: ignore[arg-type]
urllib3.exceptions.MaxRetryError: HTTPSConnectionPool(host='api.alpaca.markets', port=443): Max retries exceeded with url: /v2/account (Caused by NameResolutionError("<urllib3.connection.HTTPSConnection object at 0x110bcd280>: Failed to resolve 'api.alpaca.markets' ([Errno 8] nodename nor servname provided, or not known)"))

During handling of the above exception, another exception occurred:

Traceback (most recent call last):
  File "/Users/eduardoperezbrito/omega-vx/portfolio_snapshot.py", line 17, in <module>
    account = api.get_account()
  File "/Users/eduardoperezbrito/omega-vx/.venv/lib/python3.9/site-packages/alpaca_trade_api/rest.py", line 280, in get_account
    resp = self.get('/account')
  File "/Users/eduardoperezbrito/omega-vx/.venv/lib/python3.9/site-packages/alpaca_trade_api/rest.py", line 254, in get
    return self._request('GET', path, data)
  File "/Users/eduardoperezbrito/omega-vx/.venv/lib/python3.9/site-packages/alpaca_trade_api/rest.py", line 222, in _request
    return self._one_request(method, url, opts, retry)
  File "/Users/eduardoperezbrito/omega-vx/.venv/lib/python3.9/site-packages/alpaca_trade_api/rest.py", line 241, in _one_request
    resp = self._session.request(method, url, **opts)
  File "/Users/eduardoperezbrito/omega-vx/.venv/lib/python3.9/site-packages/requests/sessions.py", line 589, in request
    resp = self.send(prep, **send_kwargs)
  File "/Users/eduardoperezbrito/omega-vx/.venv/lib/python3.9/site-packages/requests/sessions.py", line 703, in send
    r = adapter.send(request, **kwargs)
  File "/Users/eduardoperezbrito/omega-vx/.venv/lib/python3.9/site-packages/requests/adapters.py", line 700, in send
    raise ConnectionError(e, request=request)
requests.exceptions.ConnectionError: HTTPSConnectionPool(host='api.alpaca.markets', port=443): Max retries exceeded with url: /v2/account (Caused by NameResolutionError("<urllib3.connection.HTTPSConnection object at 0x110bcd280>: Failed to resolve 'api.alpaca.markets' ([Errno 8] nodename nor servname provided, or not known)"))
/Users/eduardoperezbrito/omega-vx/.venv/lib/python3.9/site-packages/urllib3/__init__.py:35: NotOpenSSLWarning: urllib3 v2 only supports OpenSSL 1.1.1+, currently the 'ssl' module is compiled with 'LibreSSL 2.8.3'. See: https://github.com/urllib3/urllib3/issues/3020
  warnings.warn(
Traceback (most recent call last):
  File "/Users/eduardoperezbrito/omega-vx/portfolio_snapshot.py", line 17, in <module>
    account = api.get_account()
  File "/Users/eduardoperezbrito/omega-vx/.venv/lib/python3.9/site-packages/alpaca_trade_api/rest.py", line 280, in get_account
    resp = self.get('/account')
  File "/Users/eduardoperezbrito/omega-vx/.venv/lib/python3.9/site-packages/alpaca_trade_api/rest.py", line 254, in get
    return self._request('GET', path, data)
  File "/Users/eduardoperezbrito/omega-vx/.venv/lib/python3.9/site-packages/alpaca_trade_api/rest.py", line 222, in _request
    return self._one_request(method, url, opts, retry)
  File "/Users/eduardoperezbrito/omega-vx/.venv/lib/python3.9/site-packages/alpaca_trade_api/rest.py", line 248, in _one_request
    raise_api_error(resp, http_error)
  File "/Users/eduardoperezbrito/omega-vx/.venv/lib/python3.9/site-packages/alpaca_trade_api/rest.py", line 83, in raise_api_error
    raise APIError(error, http_error) from None
alpaca_trade_api.rest.APIError: request is not authorized
/Users/eduardoperezbrito/omega-vx/.venv/lib/python3.9/site-packages/urllib3/__init__.py:35: NotOpenSSLWarning: urllib3 v2 only supports OpenSSL 1.1.1+, currently the 'ssl' module is compiled with 'LibreSSL 2.8.3'. See: https://github.com/urllib3/urllib3/issues/3020
  warnings.warn(
Traceback (most recent call last):
  File "/Users/eduardoperezbrito/omega-vx/portfolio_snapshot.py", line 17, in <module>
    account = api.get_account()
  File "/Users/eduardoperezbrito/omega-vx/.venv/lib/python3.9/site-packages/alpaca_trade_api/rest.py", line 280, in get_account
    resp = self.get('/account')
  File "/Users/eduardoperezbrito/omega-vx/.venv/lib/python3.9/site-packages/alpaca_trade_api/rest.py", line 254, in get
    return self._request('GET', path, data)
  File "/Users/eduardoperezbrito/omega-vx/.venv/lib/python3.9/site-packages/alpaca_trade_api/rest.py", line 222, in _request
    return self._one_request(method, url, opts, retry)
  File "/Users/eduardoperezbrito/omega-vx/.venv/lib/python3.9/site-packages/alpaca_trade_api/rest.py", line 248, in _one_request
    raise_api_error(resp, http_error)
  File "/Users/eduardoperezbrito/omega-vx/.venv/lib/python3.9/site-packages/alpaca_trade_api/rest.py", line 83, in raise_api_error
    raise APIError(error, http_error) from None
alpaca_trade_api.rest.APIError: request is not authorized
/Users/eduardoperezbrito/omega-vx/.venv/lib/python3.9/site-packages/urllib3/__init__.py:35: NotOpenSSLWarning: urllib3 v2 only supports OpenSSL 1.1.1+, currently the 'ssl' module is compiled with 'LibreSSL 2.8.3'. See: https://github.com/urllib3/urllib3/issues/3020
  warnings.warn(
Traceback (most recent call last):
  File "/Users/eduardoperezbrito/omega-vx/portfolio_snapshot.py", line 17, in <module>
    account = api.get_account()
  File "/Users/eduardoperezbrito/omega-vx/.venv/lib/python3.9/site-packages/alpaca_trade_api/rest.py", line 280, in get_account
    resp = self.get('/account')
  File "/Users/eduardoperezbrito/omega-vx/.venv/lib/python3.9/site-packages/alpaca_trade_api/rest.py", line 254, in get
    return self._request('GET', path, data)
  File "/Users/eduardoperezbrito/omega-vx/.venv/lib/python3.9/site-packages/alpaca_trade_api/rest.py", line 222, in _request
    return self._one_request(method, url, opts, retry)
  File "/Users/eduardoperezbrito/omega-vx/.venv/lib/python3.9/site-packages/alpaca_trade_api/rest.py", line 248, in _one_request
    raise_api_error(resp, http_error)
  File "/Users/eduardoperezbrito/omega-vx/.venv/lib/python3.9/site-packages/alpaca_trade_api/rest.py", line 83, in raise_api_error
    raise APIError(error, http_error) from None
alpaca_trade_api.rest.APIError: request is not authorized
/Users/eduardoperezbrito/omega-vx/.venv/lib/python3.9/site-packages/urllib3/__init__.py:35: NotOpenSSLWarning: urllib3 v2 only supports OpenSSL 1.1.1+, currently the 'ssl' module is compiled with 'LibreSSL 2.8.3'. See: https://github.com/urllib3/urllib3/issues/3020
  warnings.warn(
Traceback (most recent call last):
  File "/Users/eduardoperezbrito/omega-vx/.venv/lib/python3.9/site-packages/alpaca/common/rest.py", line 198, in _one_request
    response.raise_for_status()
  File "/Users/eduardoperezbrito/omega-vx/.venv/lib/python3.9/site-packages/requests/models.py", line 1026, in raise_for_status
    raise HTTPError(http_error_msg, response=self)
requests.exceptions.HTTPError: 401 Client Error: Unauthorized for url: https://api.alpaca.markets/v2/account

During handling of the above exception, another exception occurred:

Traceback (most recent call last):
  File "/Users/eduardoperezbrito/omega-vx/portfolio_snapshot.py", line 17, in <module>
    account = client.get_account()
  File "/Users/eduardoperezbrito/omega-vx/.venv/lib/python3.9/site-packages/alpaca/trading/client.py", line 474, in get_account
    response = self.get("/account")
  File "/Users/eduardoperezbrito/omega-vx/.venv/lib/python3.9/site-packages/alpaca/common/rest.py", line 225, in get
    return self._request("GET", path, data, **kwargs)
  File "/Users/eduardoperezbrito/omega-vx/.venv/lib/python3.9/site-packages/alpaca/common/rest.py", line 131, in _request
    return self._one_request(method, url, opts, retry)
  File "/Users/eduardoperezbrito/omega-vx/.venv/lib/python3.9/site-packages/alpaca/common/rest.py", line 207, in _one_request
    raise APIError(error, http_error)
alpaca.common.exceptions.APIError: {"message": "unauthorized."}

/Users/eduardoperezbrito/omega-vx/.venv/lib/python3.9/site-packages/urllib3/__init__.py:35: NotOpenSSLWarning: urllib3 v2 only supports OpenSSL 1.1.1+, currently the 'ssl' module is compiled with 'LibreSSL 2.8.3'. See: https://github.com/urllib3/urllib3/issues/3020
  warnings.warn(
Traceback (most recent call last):
  File "/Users/eduardoperezbrito/omega-vx/.venv/lib/python3.9/site-packages/urllib3/connection.py", line 198, in _new_conn
    sock = connection.create_connection(
  File "/Users/eduardoperezbrito/omega-vx/.venv/lib/python3.9/site-packages/urllib3/util/connection.py", line 60, in create_connection
    for res in socket.getaddrinfo(host, port, family, socket.SOCK_STREAM):
  File "/Library/Developer/CommandLineTools/Library/Frameworks/Python3.framework/Versions/3.9/lib/python3.9/socket.py", line 953, in getaddrinfo
    for res in _socket.getaddrinfo(host, port, family, type, proto, flags):
socket.gaierror: [Errno 8] nodename nor servname provided, or not known

The above exception was the direct cause of the following exception:

Traceback (most recent call last):
  File "/Users/eduardoperezbrito/omega-vx/.venv/lib/python3.9/site-packages/urllib3/connectionpool.py", line 787, in urlopen
    response = self._make_request(
  File "/Users/eduardoperezbrito/omega-vx/.venv/lib/python3.9/site-packages/urllib3/connectionpool.py", line 488, in _make_request
    raise new_e
  File "/Users/eduardoperezbrito/omega-vx/.venv/lib/python3.9/site-packages/urllib3/connectionpool.py", line 464, in _make_request
    self._validate_conn(conn)
  File "/Users/eduardoperezbrito/omega-vx/.venv/lib/python3.9/site-packages/urllib3/connectionpool.py", line 1093, in _validate_conn
    conn.connect()
  File "/Users/eduardoperezbrito/omega-vx/.venv/lib/python3.9/site-packages/urllib3/connection.py", line 753, in connect
    self.sock = sock = self._new_conn()
  File "/Users/eduardoperezbrito/omega-vx/.venv/lib/python3.9/site-packages/urllib3/connection.py", line 205, in _new_conn
    raise NameResolutionError(self.host, self, e) from e
urllib3.exceptions.NameResolutionError: <urllib3.connection.HTTPSConnection object at 0x1075b7430>: Failed to resolve 'api.alpaca.markets' ([Errno 8] nodename nor servname provided, or not known)

The above exception was the direct cause of the following exception:

Traceback (most recent call last):
  File "/Users/eduardoperezbrito/omega-vx/.venv/lib/python3.9/site-packages/requests/adapters.py", line 667, in send
    resp = conn.urlopen(
  File "/Users/eduardoperezbrito/omega-vx/.venv/lib/python3.9/site-packages/urllib3/connectionpool.py", line 841, in urlopen
    retries = retries.increment(
  File "/Users/eduardoperezbrito/omega-vx/.venv/lib/python3.9/site-packages/urllib3/util/retry.py", line 519, in increment
    raise MaxRetryError(_pool, url, reason) from reason  # type: ignore[arg-type]
urllib3.exceptions.MaxRetryError: HTTPSConnectionPool(host='api.alpaca.markets', port=443): Max retries exceeded with url: /v2/account (Caused by NameResolutionError("<urllib3.connection.HTTPSConnection object at 0x1075b7430>: Failed to resolve 'api.alpaca.markets' ([Errno 8] nodename nor servname provided, or not known)"))

During handling of the above exception, another exception occurred:

Traceback (most recent call last):
  File "/Users/eduardoperezbrito/omega-vx/portfolio_snapshot.py", line 17, in <module>
    account = client.get_account()
  File "/Users/eduardoperezbrito/omega-vx/.venv/lib/python3.9/site-packages/alpaca/trading/client.py", line 474, in get_account
    response = self.get("/account")
  File "/Users/eduardoperezbrito/omega-vx/.venv/lib/python3.9/site-packages/alpaca/common/rest.py", line 225, in get
    return self._request("GET", path, data, **kwargs)
  File "/Users/eduardoperezbrito/omega-vx/.venv/lib/python3.9/site-packages/alpaca/common/rest.py", line 131, in _request
    return self._one_request(method, url, opts, retry)
  File "/Users/eduardoperezbrito/omega-vx/.venv/lib/python3.9/site-packages/alpaca/common/rest.py", line 195, in _one_request
    response = self._session.request(method, url, **opts)
  File "/Users/eduardoperezbrito/omega-vx/.venv/lib/python3.9/site-packages/requests/sessions.py", line 589, in request
    resp = self.send(prep, **send_kwargs)
  File "/Users/eduardoperezbrito/omega-vx/.venv/lib/python3.9/site-packages/requests/sessions.py", line 703, in send
    r = adapter.send(request, **kwargs)
  File "/Users/eduardoperezbrito/omega-vx/.venv/lib/python3.9/site-packages/requests/adapters.py", line 700, in send
    raise ConnectionError(e, request=request)
requests.exceptions.ConnectionError: HTTPSConnectionPool(host='api.alpaca.markets', port=443): Max retries exceeded with url: /v2/account (Caused by NameResolutionError("<urllib3.connection.HTTPSConnection object at 0x1075b7430>: Failed to resolve 'api.alpaca.markets' ([Errno 8] nodename nor servname provided, or not known)"))
/Users/eduardoperezbrito/omega-vx/.venv/lib/python3.9/site-packages/urllib3/__init__.py:35: NotOpenSSLWarning: urllib3 v2 only supports OpenSSL 1.1.1+, currently the 'ssl' module is compiled with 'LibreSSL 2.8.3'. See: https://github.com/urllib3/urllib3/issues/3020
  warnings.warn(
Traceback (most recent call last):
  File "/Users/eduardoperezbrito/omega-vx/.venv/lib/python3.9/site-packages/urllib3/connection.py", line 198, in _new_conn
    sock = connection.create_connection(
  File "/Users/eduardoperezbrito/omega-vx/.venv/lib/python3.9/site-packages/urllib3/util/connection.py", line 60, in create_connection
    for res in socket.getaddrinfo(host, port, family, socket.SOCK_STREAM):
  File "/Library/Developer/CommandLineTools/Library/Frameworks/Python3.framework/Versions/3.9/lib/python3.9/socket.py", line 953, in getaddrinfo
    for res in _socket.getaddrinfo(host, port, family, type, proto, flags):
socket.gaierror: [Errno 8] nodename nor servname provided, or not known

The above exception was the direct cause of the following exception:

Traceback (most recent call last):
  File "/Users/eduardoperezbrito/omega-vx/.venv/lib/python3.9/site-packages/urllib3/connectionpool.py", line 787, in urlopen
    response = self._make_request(
  File "/Users/eduardoperezbrito/omega-vx/.venv/lib/python3.9/site-packages/urllib3/connectionpool.py", line 488, in _make_request
    raise new_e
  File "/Users/eduardoperezbrito/omega-vx/.venv/lib/python3.9/site-packages/urllib3/connectionpool.py", line 464, in _make_request
    self._validate_conn(conn)
  File "/Users/eduardoperezbrito/omega-vx/.venv/lib/python3.9/site-packages/urllib3/connectionpool.py", line 1093, in _validate_conn
    conn.connect()
  File "/Users/eduardoperezbrito/omega-vx/.venv/lib/python3.9/site-packages/urllib3/connection.py", line 753, in connect
    self.sock = sock = self._new_conn()
  File "/Users/eduardoperezbrito/omega-vx/.venv/lib/python3.9/site-packages/urllib3/connection.py", line 205, in _new_conn
    raise NameResolutionError(self.host, self, e) from e
urllib3.exceptions.NameResolutionError: <urllib3.connection.HTTPSConnection object at 0x1053f3430>: Failed to resolve 'api.alpaca.markets' ([Errno 8] nodename nor servname provided, or not known)

The above exception was the direct cause of the following exception:

Traceback (most recent call last):
  File "/Users/eduardoperezbrito/omega-vx/.venv/lib/python3.9/site-packages/requests/adapters.py", line 667, in send
    resp = conn.urlopen(
  File "/Users/eduardoperezbrito/omega-vx/.venv/lib/python3.9/site-packages/urllib3/connectionpool.py", line 841, in urlopen
    retries = retries.increment(
  File "/Users/eduardoperezbrito/omega-vx/.venv/lib/python3.9/site-packages/urllib3/util/retry.py", line 519, in increment
    raise MaxRetryError(_pool, url, reason) from reason  # type: ignore[arg-type]
urllib3.exceptions.MaxRetryError: HTTPSConnectionPool(host='api.alpaca.markets', port=443): Max retries exceeded with url: /v2/account (Caused by NameResolutionError("<urllib3.connection.HTTPSConnection object at 0x1053f3430>: Failed to resolve 'api.alpaca.markets' ([Errno 8] nodename nor servname provided, or not known)"))

During handling of the above exception, another exception occurred:

Traceback (most recent call last):
  File "/Users/eduardoperezbrito/omega-vx/portfolio_snapshot.py", line 17, in <module>
    account = client.get_account()
  File "/Users/eduardoperezbrito/omega-vx/.venv/lib/python3.9/site-packages/alpaca/trading/client.py", line 474, in get_account
    response = self.get("/account")
  File "/Users/eduardoperezbrito/omega-vx/.venv/lib/python3.9/site-packages/alpaca/common/rest.py", line 225, in get
    return self._request("GET", path, data, **kwargs)
  File "/Users/eduardoperezbrito/omega-vx/.venv/lib/python3.9/site-packages/alpaca/common/rest.py", line 131, in _request
    return self._one_request(method, url, opts, retry)
  File "/Users/eduardoperezbrito/omega-vx/.venv/lib/python3.9/site-packages/alpaca/common/rest.py", line 195, in _one_request
    response = self._session.request(method, url, **opts)
  File "/Users/eduardoperezbrito/omega-vx/.venv/lib/python3.9/site-packages/requests/sessions.py", line 589, in request
    resp = self.send(prep, **send_kwargs)
  File "/Users/eduardoperezbrito/omega-vx/.venv/lib/python3.9/site-packages/requests/sessions.py", line 703, in send
    r = adapter.send(request, **kwargs)
  File "/Users/eduardoperezbrito/omega-vx/.venv/lib/python3.9/site-packages/requests/adapters.py", line 700, in send
    raise ConnectionError(e, request=request)
requests.exceptions.ConnectionError: HTTPSConnectionPool(host='api.alpaca.markets', port=443): Max retries exceeded with url: /v2/account (Caused by NameResolutionError("<urllib3.connection.HTTPSConnection object at 0x1053f3430>: Failed to resolve 'api.alpaca.markets' ([Errno 8] nodename nor servname provided, or not known)"))
/Users/eduardoperezbrito/omega-vx/.venv/lib/python3.9/site-packages/urllib3/__init__.py:35: NotOpenSSLWarning: urllib3 v2 only supports OpenSSL 1.1.1+, currently the 'ssl' module is compiled with 'LibreSSL 2.8.3'. See: https://github.com/urllib3/urllib3/issues/3020
  warnings.warn(
Traceback (most recent call last):
  File "/Users/eduardoperezbrito/omega-vx/.venv/lib/python3.9/site-packages/alpaca/common/rest.py", line 198, in _one_request
    response.raise_for_status()
  File "/Users/eduardoperezbrito/omega-vx/.venv/lib/python3.9/site-packages/requests/models.py", line 1026, in raise_for_status
    raise HTTPError(http_error_msg, response=self)
requests.exceptions.HTTPError: 401 Client Error: Unauthorized for url: https://api.alpaca.markets/v2/account

During handling of the above exception, another exception occurred:

Traceback (most recent call last):
  File "/Users/eduardoperezbrito/omega-vx/portfolio_snapshot.py", line 17, in <module>
    account = client.get_account()
  File "/Users/eduardoperezbrito/omega-vx/.venv/lib/python3.9/site-packages/alpaca/trading/client.py", line 474, in get_account
    response = self.get("/account")
  File "/Users/eduardoperezbrito/omega-vx/.venv/lib/python3.9/site-packages/alpaca/common/rest.py", line 225, in get
    return self._request("GET", path, data, **kwargs)
  File "/Users/eduardoperezbrito/omega-vx/.venv/lib/python3.9/site-packages/alpaca/common/rest.py", line 131, in _request
    return self._one_request(method, url, opts, retry)
  File "/Users/eduardoperezbrito/omega-vx/.venv/lib/python3.9/site-packages/alpaca/common/rest.py", line 207, in _one_request
    raise APIError(error, http_error)
alpaca.common.exceptions.APIError: {"message": "unauthorized."}

/Users/eduardoperezbrito/omega-vx/.venv/lib/python3.9/site-packages/urllib3/__init__.py:35: NotOpenSSLWarning: urllib3 v2 only supports OpenSSL 1.1.1+, currently the 'ssl' module is compiled with 'LibreSSL 2.8.3'. See: https://github.com/urllib3/urllib3/issues/3020
  warnings.warn(
Traceback (most recent call last):
  File "/Users/eduardoperezbrito/omega-vx/.venv/lib/python3.9/site-packages/urllib3/connection.py", line 198, in _new_conn
    sock = connection.create_connection(
  File "/Users/eduardoperezbrito/omega-vx/.venv/lib/python3.9/site-packages/urllib3/util/connection.py", line 60, in create_connection
    for res in socket.getaddrinfo(host, port, family, socket.SOCK_STREAM):
  File "/Library/Developer/CommandLineTools/Library/Frameworks/Python3.framework/Versions/3.9/lib/python3.9/socket.py", line 953, in getaddrinfo
    for res in _socket.getaddrinfo(host, port, family, type, proto, flags):
socket.gaierror: [Errno 8] nodename nor servname provided, or not known

The above exception was the direct cause of the following exception:

Traceback (most recent call last):
  File "/Users/eduardoperezbrito/omega-vx/.venv/lib/python3.9/site-packages/urllib3/connectionpool.py", line 787, in urlopen
    response = self._make_request(
  File "/Users/eduardoperezbrito/omega-vx/.venv/lib/python3.9/site-packages/urllib3/connectionpool.py", line 488, in _make_request
    raise new_e
  File "/Users/eduardoperezbrito/omega-vx/.venv/lib/python3.9/site-packages/urllib3/connectionpool.py", line 464, in _make_request
    self._validate_conn(conn)
  File "/Users/eduardoperezbrito/omega-vx/.venv/lib/python3.9/site-packages/urllib3/connectionpool.py", line 1093, in _validate_conn
    conn.connect()
  File "/Users/eduardoperezbrito/omega-vx/.venv/lib/python3.9/site-packages/urllib3/connection.py", line 753, in connect
    self.sock = sock = self._new_conn()
  File "/Users/eduardoperezbrito/omega-vx/.venv/lib/python3.9/site-packages/urllib3/connection.py", line 205, in _new_conn
    raise NameResolutionError(self.host, self, e) from e
urllib3.exceptions.NameResolutionError: <urllib3.connection.HTTPSConnection object at 0x12169b430>: Failed to resolve 'api.alpaca.markets' ([Errno 8] nodename nor servname provided, or not known)

The above exception was the direct cause of the following exception:

Traceback (most recent call last):
  File "/Users/eduardoperezbrito/omega-vx/.venv/lib/python3.9/site-packages/requests/adapters.py", line 667, in send
    resp = conn.urlopen(
  File "/Users/eduardoperezbrito/omega-vx/.venv/lib/python3.9/site-packages/urllib3/connectionpool.py", line 841, in urlopen
    retries = retries.increment(
  File "/Users/eduardoperezbrito/omega-vx/.venv/lib/python3.9/site-packages/urllib3/util/retry.py", line 519, in increment
    raise MaxRetryError(_pool, url, reason) from reason  # type: ignore[arg-type]
urllib3.exceptions.MaxRetryError: HTTPSConnectionPool(host='api.alpaca.markets', port=443): Max retries exceeded with url: /v2/account (Caused by NameResolutionError("<urllib3.connection.HTTPSConnection object at 0x12169b430>: Failed to resolve 'api.alpaca.markets' ([Errno 8] nodename nor servname provided, or not known)"))

During handling of the above exception, another exception occurred:

Traceback (most recent call last):
  File "/Users/eduardoperezbrito/omega-vx/portfolio_snapshot.py", line 17, in <module>
    account = client.get_account()
  File "/Users/eduardoperezbrito/omega-vx/.venv/lib/python3.9/site-packages/alpaca/trading/client.py", line 474, in get_account
    response = self.get("/account")
  File "/Users/eduardoperezbrito/omega-vx/.venv/lib/python3.9/site-packages/alpaca/common/rest.py", line 225, in get
    return self._request("GET", path, data, **kwargs)
  File "/Users/eduardoperezbrito/omega-vx/.venv/lib/python3.9/site-packages/alpaca/common/rest.py", line 131, in _request
    return self._one_request(method, url, opts, retry)
  File "/Users/eduardoperezbrito/omega-vx/.venv/lib/python3.9/site-packages/alpaca/common/rest.py", line 195, in _one_request
    response = self._session.request(method, url, **opts)
  File "/Users/eduardoperezbrito/omega-vx/.venv/lib/python3.9/site-packages/requests/sessions.py", line 589, in request
    resp = self.send(prep, **send_kwargs)
  File "/Users/eduardoperezbrito/omega-vx/.venv/lib/python3.9/site-packages/requests/sessions.py", line 703, in send
    r = adapter.send(request, **kwargs)
  File "/Users/eduardoperezbrito/omega-vx/.venv/lib/python3.9/site-packages/requests/adapters.py", line 700, in send
    raise ConnectionError(e, request=request)
requests.exceptions.ConnectionError: HTTPSConnectionPool(host='api.alpaca.markets', port=443): Max retries exceeded with url: /v2/account (Caused by NameResolutionError("<urllib3.connection.HTTPSConnection object at 0x12169b430>: Failed to resolve 'api.alpaca.markets' ([Errno 8] nodename nor servname provided, or not known)"))
/Users/eduardoperezbrito/omega-vx/.venv/lib/python3.9/site-packages/urllib3/__init__.py:35: NotOpenSSLWarning: urllib3 v2 only supports OpenSSL 1.1.1+, currently the 'ssl' module is compiled with 'LibreSSL 2.8.3'. See: https://github.com/urllib3/urllib3/issues/3020
  warnings.warn(
Traceback (most recent call last):
  File "/Users/eduardoperezbrito/omega-vx/.venv/lib/python3.9/site-packages/urllib3/connection.py", line 198, in _new_conn
    sock = connection.create_connection(
  File "/Users/eduardoperezbrito/omega-vx/.venv/lib/python3.9/site-packages/urllib3/util/connection.py", line 60, in create_connection
    for res in socket.getaddrinfo(host, port, family, socket.SOCK_STREAM):
  File "/Library/Developer/CommandLineTools/Library/Frameworks/Python3.framework/Versions/3.9/lib/python3.9/socket.py", line 953, in getaddrinfo
    for res in _socket.getaddrinfo(host, port, family, type, proto, flags):
socket.gaierror: [Errno 8] nodename nor servname provided, or not known

The above exception was the direct cause of the following exception:

Traceback (most recent call last):
  File "/Users/eduardoperezbrito/omega-vx/.venv/lib/python3.9/site-packages/urllib3/connectionpool.py", line 787, in urlopen
    response = self._make_request(
  File "/Users/eduardoperezbrito/omega-vx/.venv/lib/python3.9/site-packages/urllib3/connectionpool.py", line 488, in _make_request
    raise new_e
  File "/Users/eduardoperezbrito/omega-vx/.venv/lib/python3.9/site-packages/urllib3/connectionpool.py", line 464, in _make_request
    self._validate_conn(conn)
  File "/Users/eduardoperezbrito/omega-vx/.venv/lib/python3.9/site-packages/urllib3/connectionpool.py", line 1093, in _validate_conn
    conn.connect()
  File "/Users/eduardoperezbrito/omega-vx/.venv/lib/python3.9/site-packages/urllib3/connection.py", line 753, in connect
    self.sock = sock = self._new_conn()
  File "/Users/eduardoperezbrito/omega-vx/.venv/lib/python3.9/site-packages/urllib3/connection.py", line 205, in _new_conn
    raise NameResolutionError(self.host, self, e) from e
urllib3.exceptions.NameResolutionError: <urllib3.connection.HTTPSConnection object at 0x108f215b0>: Failed to resolve 'api.alpaca.markets' ([Errno 8] nodename nor servname provided, or not known)

The above exception was the direct cause of the following exception:

Traceback (most recent call last):
  File "/Users/eduardoperezbrito/omega-vx/.venv/lib/python3.9/site-packages/requests/adapters.py", line 667, in send
    resp = conn.urlopen(
  File "/Users/eduardoperezbrito/omega-vx/.venv/lib/python3.9/site-packages/urllib3/connectionpool.py", line 841, in urlopen
    retries = retries.increment(
  File "/Users/eduardoperezbrito/omega-vx/.venv/lib/python3.9/site-packages/urllib3/util/retry.py", line 519, in increment
    raise MaxRetryError(_pool, url, reason) from reason  # type: ignore[arg-type]
urllib3.exceptions.MaxRetryError: HTTPSConnectionPool(host='api.alpaca.markets', port=443): Max retries exceeded with url: /v2/account (Caused by NameResolutionError("<urllib3.connection.HTTPSConnection object at 0x108f215b0>: Failed to resolve 'api.alpaca.markets' ([Errno 8] nodename nor servname provided, or not known)"))

During handling of the above exception, another exception occurred:

Traceback (most recent call last):
  File "/Users/eduardoperezbrito/omega-vx/portfolio_snapshot.py", line 17, in <module>
    account = client.get_account()
  File "/Users/eduardoperezbrito/omega-vx/.venv/lib/python3.9/site-packages/alpaca/trading/client.py", line 474, in get_account
    response = self.get("/account")
  File "/Users/eduardoperezbrito/omega-vx/.venv/lib/python3.9/site-packages/alpaca/common/rest.py", line 225, in get
    return self._request("GET", path, data, **kwargs)
  File "/Users/eduardoperezbrito/omega-vx/.venv/lib/python3.9/site-packages/alpaca/common/rest.py", line 131, in _request
    return self._one_request(method, url, opts, retry)
  File "/Users/eduardoperezbrito/omega-vx/.venv/lib/python3.9/site-packages/alpaca/common/rest.py", line 195, in _one_request
    response = self._session.request(method, url, **opts)
  File "/Users/eduardoperezbrito/omega-vx/.venv/lib/python3.9/site-packages/requests/sessions.py", line 589, in request
    resp = self.send(prep, **send_kwargs)
  File "/Users/eduardoperezbrito/omega-vx/.venv/lib/python3.9/site-packages/requests/sessions.py", line 703, in send
    r = adapter.send(request, **kwargs)
  File "/Users/eduardoperezbrito/omega-vx/.venv/lib/python3.9/site-packages/requests/adapters.py", line 700, in send
    raise ConnectionError(e, request=request)
requests.exceptions.ConnectionError: HTTPSConnectionPool(host='api.alpaca.markets', port=443): Max retries exceeded with url: /v2/account (Caused by NameResolutionError("<urllib3.connection.HTTPSConnection object at 0x108f215b0>: Failed to resolve 'api.alpaca.markets' ([Errno 8] nodename nor servname provided, or not known)"))
/Users/eduardoperezbrito/omega-vx/.venv/lib/python3.9/site-packages/urllib3/__init__.py:35: NotOpenSSLWarning: urllib3 v2 only supports OpenSSL 1.1.1+, currently the 'ssl' module is compiled with 'LibreSSL 2.8.3'. See: https://github.com/urllib3/urllib3/issues/3020
  warnings.warn(
âœ… Portfolio snapshot logged:
ðŸ•’ Time: 2025-10-17 15:59:02
ðŸ’¼ Equity: $4680.25
ðŸ’µ Cash: $-4578.80
ðŸ“ˆ Portfolio Value: $4680.25
